Workbook

Sheet Datos
A1: pais | B1: region | C1: anio | D1: zee_km2 | E1: linea_costa_km | F1: produccion_captura_ton | G1: produccion_acuicultura_ton | H1: produccion_total_ton | I1: ratio_produccion_zee_ton_km2 | J1: participacion_mundial_pct | K1: especie_principal | L1: grupo_isscaap | M1: tipo_produccion_predominante | N1: tasa_crecimiento_anual_pct | O1: fuente_dato
A2: Argentina | B2: Sudamérica | C2: 2000 | D2: 1159063 | E2: 4989 | F2: 921800 | G2: 1784 | H2: =F2+G2 -> 923584 | I2: =H2/D2 -> 0.79683676 | J2: =H2/VLOOKUP(C2,Referencia_Mundial!$A:$B,2,FALSE())*100 -> 0.67027385 | K2: Argentine shortfin squid | L2: Squids, cuttlefishes, octopuses | M2: =IF(F2>=G2,"Captura silvestre","Acuicultura") -> Captura silvestre | O2: FAO FishStatJ - Global Production 2025 (dato real, valores oficiales/estimados FAO)
A3: Argentina | B3: Sudamérica | C3: 2001 | D3: 1159063 | E3: 4989 | F3: 931081 | G3: 1340 | H3: =F3+G3 -> 932421 | I3: =H3/D3 -> 0.80446102 | J3: =H3/VLOOKUP(C3,Referencia_Mundial!$A:$B,2,FALSE())*100 -> 0.67789671 | K3: Argentine hake | L3: Cods, hakes, haddocks | M3: =IF(F3>=G3,"Captura silvestre","Acuicultura") -> Captura silvestre | N3: =(H3-H2)/H2*100 -> 0.95681606 | O3: FAO FishStatJ - Global Production 2025 (dato real, valores oficiales/estimados FAO)
A4: Argentina | B4: Sudamérica | C4: 2002 | D4: 1159063 | E4: 4989 | F4: 946185 | G4: 1457 | H4: =F4+G4 -> 947642 | I4: =H4/D4 -> 0.81759318 | J4: =H4/VLOOKUP(C4,Referencia_Mundial!$A:$B,2,FALSE())*100 -> 0.67199795 | K4: Argentine hake | L4: Cods, hakes, haddocks | M4: =IF(F4>=G4,"Captura silvestre","Acuicultura") -> Captura silvestre | N4: =(H4-H3)/H3*100 -> 1.6324171 | O4: FAO FishStatJ - Global Production 2025 (dato real, valores oficiales/estimados FAO)
A5: Argentina | B5: Sudamérica | C5: 2003 | D5: 1159063 | E5: 4989 | F5: 910200 | G5: 1647 | H5: =F5+G5 -> 911847 | I5: =H5/D5 -> 0.78671047 | J5: =H5/VLOOKUP(C5,Referencia_Mundial!$A:$B,2,FALSE())*100 -> 0.6460627 | K5: Argentine hake | L5: Cods, hakes, haddocks | M5: =IF(F5>=G5,"Captura silvestre","Acuicultura") -> Captura silvestre | N5: =(H5-H4)/H4*100 -> -3.7772703 | O5: FAO FishStatJ - Global Production 2025 (dato real, valores oficiales/estimados FAO)
A6: Argentina | B6: Sudamérica | C6: 2004 | D6: 1159063 | E6: 4989 | F6: 944846 | G6: 1848 | H6: =F6+G6 -> 946694 | I6: =H6/D6 -> 0.81677527 | J6: =H6/VLOOKUP(C6,Referencia_Mundial!$A:$B,2,FALSE())*100 -> 0.63095336 | K6: Argentine hake | L6: Cods, hakes, haddocks | M6: =IF(F6>=G6,"Captura silvestre","Acuicultura") -> Captura silvestre | N6: =(H6-H5)/H5*100 -> 3.8215841 | O6: FAO FishStatJ - Global Production 2025 (dato real, valores oficiales/estimados FAO)
A7: Argentina | B7: Sudamérica | C7: 2005 | D7: 1159063 | E7: 4989 | F7: 929937 | G7: 2057 | H7: =F7+G7 -> 931994 | I7: =H7/D7 -> 0.80409262 | J7: =H7/VLOOKUP(C7,Referencia_Mundial!$A:$B,2,FALSE())*100 -> 0.60943051 | K7: Argentine hake | L7: Cods, hakes, haddocks | M7: =IF(F7>=G7,"Captura silvestre","Acuicultura") -> Captura silvestre | N7: =(H7-H6)/H6*100 -> -1.5527721 | O7: FAO FishStatJ - Global Production 2025 (dato real, valores oficiales/estimados FAO)
A8: Argentina | B8: Sudamérica | C8: 2006 | D8: 1159063 | E8: 4989 | F8: 1171980 | G8: 2528 | H8: =F8+G8 -> 1174508 | I8: =H8/D8 -> 1.0133254 | J8: =H8/VLOOKUP(C8,Referencia_Mundial!$A:$B,2,FALSE())*100 -> 0.76133603 | K8: Argentine hake | L8: Cods, hakes, haddocks | M8: =IF(F8>=G8,"Captura silvestre","Acuicultura") -> Captura silvestre | N8: =(H8-H7)/H7*100 -> 26.020983 | O8: FAO FishStatJ - Global Production 2025 (dato real, valores oficiales/estimados FAO)
A9: Argentina | B9: Sudamérica | C9: 2007 | D9: 1159063 | E9: 4989 | F9: 985409 | G9: 2957 | H9: =F9+G9 -> 988366 | I9: =H9/D9 -> 0.85272845 | J9: =H9/VLOOKUP(C9,Referencia_Mundial!$A:$B,2,FALSE())*100 -> 0.62557019 | K9: Argentine hake | L9: Cods, hakes, haddocks | M9: =IF(F9>=G9,"Captura silvestre","Acuicultura") -> Captura silvestre | N9: =(H9-H8)/H8*100 -> -15.848508 | O9: FAO FishStatJ - Global Production 2025 (dato real, valores oficiales/estimados FAO)
A10: Argentina | B10: Sudamérica | C10: 2008 | D10: 1159063 | E10: 4989 | F10: 995083 | G10: 2700 | H10: =F10+G10 -> 997783 | I10: =H10/D10 -> 0.86085312 | J10: =H10/VLOOKUP(C10,Referencia_Mundial!$A:$B,2,FALSE())*100 -> 0.6197309 | K10: Argentine hake | L10: Cods, hakes, haddocks | M10: =IF(F10>=G10,"Captura silvestre","Acuicultura") -> Captura silvestre | N10: =(H10-H9)/H9*100 -> 0.9527847 | O10: FAO FishStatJ - Global Production 2025 (dato real, valores oficiales/estimados FAO)
A11: Argentina | B11: Sudamérica | C11: 2009 | D11: 1159063 | E11: 4989 | F11: 861974 | G11: 2583 | H11: =F11+G11 -> 864557 | I11: =H11/D11 -> 0.74591027 | J11: =H11/VLOOKUP(C11,Referencia_Mundial!$A:$B,2,FALSE())*100 -> 0.52706962 | K11: Argentine hake | L11: Cods, hakes, haddocks | M11: =IF(F11>=G11,"Captura silvestre","Acuicultura") -> Captura silvestre | N11: =(H11-H10)/H10*100 -> -13.352202 | O11: FAO FishStatJ - Global Production 2025 (dato real, valores oficiales/estimados FAO)
A12: Argentina | B12: Sudamérica | C12: 2010 | D12: 1159063 | E12: 4989 | F12: 811749 | G12: 2654.4 | H12: =F12+G12 -> 814403.4 | I12: =H12/D12 -> 0.70263946 | J12: =H12/VLOOKUP(C12,Referencia_Mundial!$A:$B,2,FALSE())*100 -> 0.48970837 | K12: Argentine hake | L12: Cods, hakes, haddocks | M12: =IF(F12>=G12,"Captura silvestre","Acuicultura") -> Captura silvestre | N12: =(H12-H11)/H11*100 -> -5.801075 | O12: FAO FishStatJ - Global Production 2025 (dato real, valores oficiales/estimados FAO)
A13: Argentina | B13: Sudamérica | C13: 2011 | D13: 1159063 | E13: 4989 | F13: 793308 | G13: 3193.2 | H13: =F13+G13 -> 796501.2 | I13: =H13/D13 -> 0.68719405 | J13: =H13/VLOOKUP(C13,Referencia_Mundial!$A:$B,2,FALSE())*100 -> 0.45678193 | K13: Argentine hake | L13: Cods, hakes, haddocks | M13: =IF(F13>=G13,"Captura silvestre","Acuicultura") -> Captura silvestre | N13: =(H13-H12)/H12*100 -> -2.1981981 | O13: FAO FishStatJ - Global Production 2025 (dato real, valores oficiales/estimados FAO)
A14: Argentina | B14: Sudamérica | C14: 2012 | D14: 1159063 | E14: 4989 | F14: 738060 | G14: 2958.4 | H14: =F14+G14 -> 741018.4 | I14: =H14/D14 -> 0.63932539 | J14: =H14/VLOOKUP(C14,Referencia_Mundial!$A:$B,2,FALSE())*100 -> 0.41613615 | K14: Argentine hake | L14: Cods, hakes, haddocks | M14: =IF(F14>=G14,"Captura silvestre","Acuicultura") -> Captura silvestre | N14: =(H14-H13)/H13*100 -> -6.965815 | O14: FAO FishStatJ - Global Production 2025 (dato real, valores oficiales/estimados FAO)
... A25: Argentina | B25: Sudamérica | C25: 2023 | D25: 1159063 | E25: 4989 | F25: 827233 | G25: 5516 | H25: =F25+G25 -> 832749 | I25: =H25/D25 -> 0.71846742 | J25: =H25/VLOOKUP(C25,Referencia_Mundial!$A:$B,2,FALSE())*100 -> 0.36539559 | K25: Argentine hake | L25: Cods, hakes, haddocks | M25: =IF(F25>=G25,"Captura silvestre","Acuicultura") -> Captura silvestre | N25: =(H25-H24)/H24*100 -> -2.4626755 | O25: FAO FishStatJ - Global Production 2025 (dato real, valores oficiales/estimados FAO)
A26: Chile | B26: Sudamérica | C26: 2000 | D26: 3648532 | E26: 6435 | F26: 4547594 | G26: 425058 | H26: =F26+G26 -> 4972652 | I26: =H26/D26 -> 1.3629186 | J26: =H26/VLOOKUP(C26,Referencia_Mundial!$A:$B,2,FALSE())*100 -> 3.6088094 | K26: Anchoveta(=Peruvian anchovy) | L26: Herrings, sardines, anchovies | M26: =IF(F26>=G26,"Captura silvestre","Acuicultura") -> Captura silvestre | O26: FAO FishStatJ - Global Production 2025 (dato real, valores oficiales/estimados FAO)
A27: Chile | B27: Sudamérica | C27: 2001 | D27: 3648532 | E27: 6435 | F27: 4031799 | G27: 631634 | H27: =F27+G27 -> 4663433 | I27: =H27/D27 -> 1.2781669 | J27: =H27/VLOOKUP(C27,Referencia_Mundial!$A:$B,2,FALSE())*100 -> 3.390449 | K27: Chilean jack mackerel | L27: Miscellaneous pelagic fishes | M27: =IF(F27>=G27,"Captura silvestre","Acuicultura") -> Captura silvestre | N27: =(H27-H26)/H26*100 -> -6.2183921 | O27: FAO FishStatJ - Global Production 2025 (dato real, valores oficiales/estimados FAO)
A28: Chile | B28: Sudamérica | C28: 2002 | D28: 3648532 | E28: 6435 | F28: 4515437 | G28: 617303 | H28: =F28+G28 -> 5132740 | I28: =H28/D28 -> 1.4067959 | J28: =H28/VLOOKUP(C28,Referencia_Mundial!$A:$B,2,FALSE())*100 -> 3.6397614 | K28: Anchoveta(=Peruvian anchovy) | L28: Herrings, sardines, anchovies | M28: =IF(F28>=G28,"Captura silvestre","Acuicultura") -> Captura silvestre | N28: =(H28-H27)/H27*100 -> 10.063552 | O28: FAO FishStatJ - Global Production 2025 (dato real, valores oficiales/estimados FAO)
A29: Chile | B29: Sudamérica | C29: 2003 | D29: 3648532 | E29: 6435 | F29: 3921103 | G29: 607338 | H29: =F29+G29 -> 4528441 | I29: =H29/D29 -> 1.241168 | J29: =H29/VLOOKUP(C29,Referencia_Mundial!$A:$B,2,FALSE())*100 -> 3.2084953 | K29: Chilean jack mackerel | L29: Miscellaneous pelagic fishes | M29: =IF(F29>=G29,"Captura silvestre","Acuicultura") -> Captura silvestre | N29: =(H29-H28)/H28*100 -> -11.773419 | O29: FAO FishStatJ - Global Production 2025 (dato real, valores oficiales/estimados FAO)
A30: Chile | B30: Sudamérica | C30: 2004 | D30: 3648532 | E30: 6435 | F30: 5317385 | G30: 696157 | H30: =F30+G30 -> 6013542 | I30: =H30/D30 -> 1.6482086 | J30: =H30/VLOOKUP(C30,Referencia_Mundial!$A:$B,2,FALSE())*100 -> 4.0079102 | K30: Anchoveta(=Peruvian anchovy) | L30: Herrings, sardines, anchovies | M30: =IF(F30>=G30,"Captura silvestre","Acuicultura") -> Captura silvestre | N30: =(H30-H29)/H29*100 -> 32.794973 | O30: FAO FishStatJ - Global Production 2025 (dato real, valores oficiales/estimados FAO)
A31: Chile | B31: Sudamérica | C31: 2005 | D31: 3648532 | E31: 6435 | F31: 4738165 | G31: 739368 | H31: =F31+G31 -> 5477533 | I31: =H31/D31 -> 1.5012978 | J31: =H31/VLOOKUP(C31,Referencia_Mundial!$A:$B,2,FALSE())*100 -> 3.5817567 | K31: Anchoveta(=Peruvian anchovy) | L31: Herrings, sardines, anchovies | M31: =IF(F31>=G31,"Captura silvestre","Acuicultura") -> Captura silvestre | N31: =(H31-H30)/H30*100 -> -8.9133659 | O31: FAO FishStatJ - Global Production 2025 (dato real, valores oficiales/estimados FAO)
A32: Chile | B32: Sudamérica | C32: 2006 | D32: 3648532 | E32: 6435 | F32: 4461856 | G32: 832329 | H32: =F32+G32 -> 5294185 | I32: =H32/D32 -> 1.4510452 | J32: =H32/VLOOKUP(C32,Referencia_Mundial!$A:$B,2,FALSE())*100 -> 3.4317806 | K32: Chilean jack mackerel | L32: Miscellaneous pelagic fishes | M32: =IF(F32>=G32,"Captura silvestre","Acuicultura") -> Captura silvestre | N32: =(H32-H31)/H31*100 -> -3.3472733 | O32: FAO FishStatJ - Global Production 2025 (dato real, valores oficiales/estimados FAO)
A33: Chile | B33: Sudamérica | C33: 2007 | D33: 3648532 | E33: 6435 | F33: 4132854 | G33: 806166 | H33: =F33+G33 -> 4939020 | I33: =H33/D33 -> 1.3537006 | J33: =H33/VLOOKUP(C33,Referencia_Mundial!$A:$B,2,FALSE())*100 -> 3.1260724 | K33: Anchoveta(=Peruvian anchovy) | L33: Herrings, sardines, anchovies | M33: =IF(F33>=G33,"Captura silvestre","Acuicultura") -> Captura silvestre | N33: =(H33-H32)/H32*100 -> -6.7085869 | O33: FAO FishStatJ - Global Production 2025 (dato real, valores oficiales/estimados FAO)
A34: Chile | B34: Sudamérica | C34: 2008 | D34: 3648532 | E34: 6435 | F34: 3939379 | G34: 870845 | H34: =F34+G34 -> 4810224 | I34: =H34/D34 -> 1.3183998 | J34: =H34/VLOOKUP(C34,Referencia_Mundial!$A:$B,2,FALSE())*100 -> 2.9876681 | K34: Anchoveta(=Peruvian anchovy) | L34: Herrings, sardines, anchovies | M34: =IF(F34>=G34,"Captura silvestre","Acuicultura") -> Captura silvestre | N34: =(H34-H33)/H33*100 -> -2.6077238 | O34: FAO FishStatJ - Global Production 2025 (dato real, valores oficiales/estimados FAO)
A35: Chile | B35: Sudamérica | C35: 2009 | D35: 3648532 | E35: 6435 | F35: 3821818 | G35: 881084 | H35: =F35+G35 -> 4702902 | I35: =H35/D35 -> 1.2889847 | J35: =H35/VLOOKUP(C35,Referencia_Mundial!$A:$B,2,FALSE())*100 -> 2.8670831 | K35: Anchoveta(=Peruvian anchovy) | L35: Herrings, sardines, anchovies | M35: =IF(F35>=G35,"Captura silvestre","Acuicultura") -> Captura silvestre | N35: =(H35-H34)/H34*100 -> -2.2311227 | O35: FAO FishStatJ - Global Production 2025 (dato real, valores oficiales/estimados FAO)
A36: Chile | B36: Sudamérica | C36: 2010 | D36: 3648532 | E36: 6435 | F36: 3048316 | G36: 713241 | H36: =F36+G36 -> 3761557 | I36: =H36/D36 -> 1.0309782 | J36: =H36/VLOOKUP(C36,Referencia_Mundial!$A:$B,2,FALSE())*100 -> 2.2618593 | K36: Anchoveta(=Peruvian anchovy) | L36: Herrings, sardines, anchovies | M36: =IF(F36>=G36,"Captura silvestre","Acuicultura") -> Captura silvestre | N36: =(H36-H35)/H35*100 -> -20.016258 | O36: FAO FishStatJ - Global Production 2025 (dato real, valores oficiales/estimados FAO)
A37: Chile | B37: Sudamérica | C37: 2011 | D37: 3648532 | E37: 6435 | F37: 3466956 | G37: 969539 | H37: =F37+G37 -> 4436495 | I37: =H37/D37 -> 1.2159671 | J37: =H37/VLOOKUP(C37,Referencia_Mundial!$A:$B,2,FALSE())*100 -> 2.5442658 | K37: Anchoveta(=Peruvian anchovy) | L37: Herrings, sardines, anchovies | M37: =IF(F37>=G37,"Captura silvestre","Acuicultura") -> Captura silvestre | N37: =(H37-H36)/H36*100 -> 17.943049 | O37: FAO FishStatJ - Global Production 2025 (dato real, valores oficiales/estimados FAO)
A38: Chile | B38: Sudamérica | C38: 2012 | D38: 3648532 | E38: 6435 | F38: 3007536.3 | G38: 1075547 | H38: =F38+G38 -> 4083083.3 | I38: =H38/D38 -> 1.1191031 | J38: =H38/VLOOKUP(C38,Referencia_Mundial!$A:$B,2,FALSE())*100 -> 2.2929506 | K38: Anchoveta(=Peruvian anchovy) | L38: Herrings, sardines, anchovies | M38: =IF(F38>=G38,"Captura silvestre","Acuicultura") -> Captura silvestre | N38: =(H38-H37)/H37*100 -> -7.9660115 | O38: FAO FishStatJ - Global Production 2025 (dato real, valores oficiales/estimados FAO)
... A49: Chile | B49: Sudamérica | C49: 2023 | D49: 3648532 | E49: 6435 | F49: 2596488.4 | G49: 1502919 | H49: =F49+G49 -> 4099407.4 | I49: =H49/D49 -> 1.1235772 | J49: =H49/VLOOKUP(C49,Referencia_Mundial!$A:$B,2,FALSE())*100 -> 1.7987478 | K49: Chilean jack mackerel | L49: Miscellaneous pelagic fishes | M49: =IF(F49>=G49,"Captura silvestre","Acuicultura") -> Captura silvestre | N49: =(H49-H48)/H48*100 -> -2.7473296 | O49: FAO FishStatJ - Global Production 2025 (dato real, valores oficiales/estimados FAO)
A50: China | B50: Asia | C50: 2000 | D50: 877019 | E50: 14500 | F50: 14823866 | G50: 29749708 | H50: =F50+G50 -> 44573574 | I50: =H50/D50 -> 50.823955 | J50: =H50/VLOOKUP(C50,Referencia_Mundial!$A:$B,2,FALSE())*100 -> 32.348439 | K50: Japanese kelp | L50: Brown seaweeds | M50: =IF(F50>=G50,"Captura silvestre","Acuicultura") -> Acuicultura | O50: FAO FishStatJ - Global Production 2025 (dato real, valores oficiales/estimados FAO)
A51: China | B51: Asia | C51: 2001 | D51: 877019 | E51: 14500 | F51: 14403875 | G51: 31102502 | H51: =F51+G51 -> 45506377 | I51: =H51/D51 -> 51.887561 | J51: =H51/VLOOKUP(C51,Referencia_Mundial!$A:$B,2,FALSE())*100 -> 33.084436 | K51: Japanese kelp | L51: Brown seaweeds | M51: =IF(F51>=G51,"Captura silvestre","Acuicultura") -> Acuicultura | N51: =(H51-H50)/H50*100 -> 2.0927265 | O51: FAO FishStatJ - Global Production 2025 (dato real, valores oficiales/estimados FAO)
A52: China | B52: Asia | C52: 2002 | D52: 877019 | E52: 14500 | F52: 14426596 | G52: 33160273 | H52: =F52+G52 -> 47586869 | I52: =H52/D52 -> 54.259793 | J52: =H52/VLOOKUP(C52,Referencia_Mundial!$A:$B,2,FALSE())*100 -> 33.745105 | K52: Japanese kelp | L52: Brown seaweeds | M52: =IF(F52>=G52,"Captura silvestre","Acuicultura") -> Acuicultura | N52: =(H52-H51)/H51*100 -> 4.5718691 | O52: FAO FishStatJ - Global Production 2025 (dato real, valores oficiales/estimados FAO)
A53: China | B53: Asia | C53: 2003 | D53: 877019 | E53: 14500 | F53: 14598934 | G53: 34891716 | H53: =F53+G53 -> 49490650 | I53: =H53/D53 -> 56.430533 | J53: =H53/VLOOKUP(C53,Referencia_Mundial!$A:$B,2,FALSE())*100 -> 35.065162 | K53: Japanese kelp | L53: Brown seaweeds | M53: =IF(F53>=G53,"Captura silvestre","Acuicultura") -> Acuicultura | N53: =(H53-H52)/H52*100 -> 4.0006435 | O53: FAO FishStatJ - Global Production 2025 (dato real, valores oficiales/estimados FAO)
A54: China | B54: Asia | C54: 2004 | D54: 877019 | E54: 14500 | F54: 14786243 | G54: 37172411 | H54: =F54+G54 -> 51958654 | I54: =H54/D54 -> 59.244616 | J54: =H54/VLOOKUP(C54,Referencia_Mundial!$A:$B,2,FALSE())*100 -> 34.629444 | K54: Japanese kelp | L54: Brown seaweeds | M54: =IF(F54>=G54,"Captura silvestre","Acuicultura") -> Acuicultura | N54: =(H54-H53)/H53*100 -> 4.9868086 | O54: FAO FishStatJ - Global Production 2025 (dato real, valores oficiales/estimados FAO)
A55: China | B55: Asia | C55: 2005 | D55: 877019 | E55: 14500 | F55: 14850730 | G55: 38943267 | H55: =F55+G55 -> 53793997 | I55: =H55/D55 -> 61.337322 | J55: =H55/VLOOKUP(C55,Referencia_Mundial!$A:$B,2,FALSE())*100 -> 35.175874 | K55: Japanese kelp | L55: Brown seaweeds | M55: =IF(F55>=G55,"Captura silvestre","Acuicultura") -> Acuicultura | N55: =(H55-H54)/H54*100 -> 3.5323144 | O55: FAO FishStatJ - Global Production 2025 (dato real, valores oficiales/estimados FAO)
A56: China | B56: Asia | C56: 2006 | D56: 877019 | E56: 14500 | F56: 14995706 | G56: 40911092 | H56: =F56+G56 -> 55906798 | I56: =H56/D56 -> 63.746393 | J56: =H56/VLOOKUP(C56,Referencia_Mundial!$A:$B,2,FALSE())*100 -> 36.239735 | K56: Japanese kelp | L56: Brown seaweeds | M56: =IF(F56>=G56,"Captura silvestre","Acuicultura") -> Acuicultura | N56: =(H56-H55)/H55*100 -> 3.9275767 | O56: FAO FishStatJ - Global Production 2025 (dato real, valores oficiales/estimados FAO)
A57: China | B57: Asia | C57: 2007 | D57: 877019 | E57: 14500 | F57: 14987636 | G57: 42530160 | H57: =F57+G57 -> 57517796 | I57: =H57/D57 -> 65.583296 | J57: =H57/VLOOKUP(C57,Referencia_Mundial!$A:$B,2,FALSE())*100 -> 36.404954 | K57: Japanese kelp | L57: Brown seaweeds | M57: =IF(F57>=G57,"Captura silvestre","Acuicultura") -> Acuicultura | N57: =(H57-H56)/H56*100 -> 2.8815795 | O57: FAO FishStatJ - Global Production 2025 (dato real, valores oficiales/estimados FAO)
A58: China | B58: Asia | C58: 2008 | D58: 877019 | E58: 14500 | F58: 15157263 | G58: 44072887 | H58: =F58+G58 -> 59230150 | I58: =H58/D58 -> 67.535766 | J58: =H58/VLOOKUP(C58,Referencia_Mundial!$A:$B,2,FALSE())*100 -> 36.788314 | K58: Japanese kelp | L58: Brown seaweeds | M58: =IF(F58>=G58,"Captura silvestre","Acuicultura") -> Acuicultura | N58: =(H58-H57)/H57*100 -> 2.9770845 | O58: FAO FishStatJ - Global Production 2025 (dato real, valores oficiales/estimados FAO)
A59: China | B59: Asia | C59: 2009 | D59: 877019 | E59: 14500 | F59: 15062980 | G59: 46062876 | H59: =F59+G59 -> 61125856 | I59: =H59/D59 -> 69.697299 | J59: =H59/VLOOKUP(C59,Referencia_Mundial!$A:$B,2,FALSE())*100 -> 37.264844 | K59: Japanese kelp | L59: Brown seaweeds | M59: =IF(F59>=G59,"Captura silvestre","Acuicultura") -> Acuicultura | N59: =(H59-H58)/H58*100 -> 3.2005761 | O59: FAO FishStatJ - Global Production 2025 (dato real, valores oficiales/estimados FAO)
A60: China | B60: Asia | C60: 2010 | D60: 877019 | E60: 14500 | F60: 15054057 | G60: 47789757 | H60: =F60+G60 -> 62843814 | I60: =H60/D60 -> 71.65616 | J60: =H60/VLOOKUP(C60,Referencia_Mundial!$A:$B,2,FALSE())*100 -> 37.788572 | K60: Japanese kelp | L60: Brown seaweeds | M60: =IF(F60>=G60,"Captura silvestre","Acuicultura") -> Acuicultura | N60: =(H60-H59)/H59*100 -> 2.8105261 | O60: FAO FishStatJ - Global Production 2025 (dato real, valores oficiales/estimados FAO)
...

Sheet Diccionario_Variables
A1: Variable | B1: Tipo | C1: Origen del dato | D1: Para qué sirve
A2: pais | B2: Categórica | C2: FAO CL_FI_COUNTRY_GROUPS (real) | D2: Identificar y comparar entre países
A3: region | B3: Categórica | C3: FAO CL_FI_COUNTRY_GROUPS (real) | D3: Agrupar comparaciones regionales
A4: anio | B4: Fecha (numérica) | C4: FAO Global_production_quantity (real) | D4: Series de tiempo, 2000-2023
A5: zee_km2 | B5: Numérica | C5: Marine Regions / World Bank (externo, no FAO) | D5: Superficie marítima disponible (ZEE)
A6: linea_costa_km | B6: Numérica | C6: CIA World Factbook (externo, no FAO) | D6: Variable de control geográfico
A7: produccion_captura_ton | B7: Numérica | C7: FAO, fuente=CAPTURE (real) | D7: Producción anual por pesca extractiva
A8: produccion_acuicultura_ton | B8: Numérica | C8: FAO, fuente=FRESHWATER+BRACKISHWATER+MARINE (real) | D8: Producción anual por cultivo
A9: produccion_total_ton | B9: Numérica (calculada) | C9: Captura + Acuicultura (fórmula) | D9: Indicador principal de volumen producido
A10: ratio_produccion_zee_ton_km2 | B10: Numérica (calculada) | C10: Producción real / ZEE externa (fórmula) | D10: Eficiencia de aprovechamiento del mar
A11: participacion_mundial_pct | B11: Numérica (calculada) | C11: Producción real país / producción mundial real (fórmula, FAO) | D11: % sobre la producción mundial total
A12: especie_principal | B12: Categórica | C12: FAO CL_FI_SPECIES_GROUPS, especie con mayor volumen real | D12: Identificar especie dominante por país-año
... A16: fuente_dato | B16: Categórica | C16: Metadato | D16: Trazabilidad: FAO real vs. fuente externa

Sheet Referencia_Mundial
A1: anio | B1: produccion_mundial_ton | C1: fuente
A2: 2000 | B2: 1.3779204e+08 | C2: FAO FishStatJ - Global Production 2025 (suma mundial real, todas las fuentes/países/especies)
A3: 2001 | B3: 1.3754618e+08 | C3: FAO FishStatJ - Global Production 2025 (suma mundial real, todas las fuentes/países/especies)
A4: 2002 | B4: 1.4101858e+08 | C4: FAO FishStatJ - Global Production 2025 (suma mundial real, todas las fuentes/países/especies)
A5: 2003 | B5: 1.4113909e+08 | C5: FAO FishStatJ - Global Production 2025 (suma mundial real, todas las fuentes/países/especies)
A6: 2004 | B6: 1.5004184e+08 | C6: FAO FishStatJ - Global Production 2025 (suma mundial real, todas las fuentes/países/especies)
A7: 2005 | B7: 1.5292867e+08 | C7: FAO FishStatJ - Global Production 2025 (suma mundial real, todas las fuentes/países/especies)
A8: 2006 | B8: 1.5426933e+08 | C8: FAO FishStatJ - Global Production 2025 (suma mundial real, todas las fuentes/países/especies)
A9: 2007 | B9: 1.5799442e+08 | C9: FAO FishStatJ - Global Production 2025 (suma mundial real, todas las fuentes/países/especies)
A10: 2008 | B10: 1.6100262e+08 | C10: FAO FishStatJ - Global Production 2025 (suma mundial real, todas las fuentes/países/especies)
A11: 2009 | B11: 1.6403089e+08 | C11: FAO FishStatJ - Global Production 2025 (suma mundial real, todas las fuentes/países/especies)
A12: 2010 | B12: 1.6630375e+08 | C12: FAO FishStatJ - Global Production 2025 (suma mundial real, todas las fuentes/países/especies)
A13: 2011 | B13: 1.7437231e+08 | C13: FAO FishStatJ - Global Production 2025 (suma mundial real, todas las fuentes/países/especies)
... A25: 2023 | B25: 2.279034e+08 | C25: FAO FishStatJ - Global Production 2025 (suma mundial real, todas las fuentes/países/especies)

Sheet Notas_Metodologicas
A1: NOTAS METODOLÓGICAS
A3: Fuente principal | B3: FAO FishStatJ - Global Production Quantity 2025 (datos reales 1950-2023, descarga oficial)
A4: Países incluidos | B4: Argentina, Chile, Perú, Noruega, Islandia, Vietnam, China
A5: Periodo analizado | B5: 2000-2023 (24 años)
A6: Filtros aplicados | B6: MEASURE = Q_tlw (toneladas, peso vivo); se excluyeron STATUS L/M/O (valores ausentes/no aplicables)
A7: Captura vs Acuicultura | B7: CAPTURE = captura silvestre; FRESHWATER+BRACKISHWATER+MARINE = acuicultura (clasificación oficial FAO)
A8: Producción mundial | B8: Suma real de TODO el dataset FAO (todos los países y especies) por año, no es una estimación
A9: Especie principal | B9: Especie con mayor volumen (ton) reportado ese país-año, según código FAO ASFIS
A11: DATOS NO DISPONIBLES EN ESTE DATASET FAO (requieren fuente externa)
A12: zee_km2 / linea_costa_km | B12: FAO Production no incluye geografía marítima de cada país. Se usaron valores de Marine Regions / World Bank EEZ database como aproximación de orden de magnitud. Para precisión total, reemplazar por fuente oficial nacional o Sea Around Us.
A13: valor_exportado_usd / empleo_sector_personas | B13: No incluidos en esta versión: requieren el dataset FAO de Comercio (Trade) y estadísticas de empleo (ILO/Ministerios), que no fueron provistos en esta carga. Se eliminaron de esta tabla para no mezclar datos reales con estimaciones.
A15: Próximo paso sugerido | B15: Incorporar FAO Global Trade dataset para valor_exportado_usd real, y precisar ZEE con fuente geoespacial oficial.
